Workbook
Name Bagiai: Dashboard!$J$53

Sheet Dashboard
E2: Welcome to the District Code Record
F5: Welcome to the raw district coding system
F6: The purpose of this project is to consolidate codes for all district, parish, seket and congregation of ELCPNG
B8: District Code Records | F8: The coding per district, seket, parish and congregation are respectively arraged in three alphanumeric character as follows:
B9: as of March 2023 | F9: District code | G9: Dxx | H9: Distict codes begin with the alphabet "D" and folled by two digit number. Example, D01, D03 etc…
F10: Seket Code | G10: Dxx-Sxx | H10: Seket code is a combination of its respective district code followed by a three alphanumeric character beginning with the letter "S"
H11: for example: D01-S04 which represent Seket 4 in District 1
B12: District | F12: Parish Code | G12: Dxx-Sxx-Pxx | H12: The Parish code captures the district and seket code where it is under followed by its respective pCode wich is a three alphanumeric beginning with the letter "P"
H13: for example: D04-S05-P02
F14: Congregation Code | G14: Dxx-Sxx-Pxx-Kxx | H14: The Congregation code captures the parish code of its respective parish then followed by its kCode which is a alphanumeric of three characters beginning with "K"
B15: Seket | H15: for example: D08-S05-P-04-K03
F16: sCode, pCode, kCode | H16: you would see this header sCode in Seket, pCode in Parish and kCode in Congregation. These are the intermediate codes that are entered inorder to generate the respective
H17: seketCode, parishCode and congCode
B18: Parish
F19: Summary
F20: These are the summary of the table listings. You will realise that is not fully updated yet per the summary totals. The updating is still in progress as of the date this system was set up
B21: Congregation
F22: 1. Overall Total | I22: 2. Total per districts | N22: 3. List Sekets per districts
F23: Disticts | G23: =ROWS(tblDistrict[]) -> 17 | I23: District | J23: tot Seket | K23: tot Parish | L23: tot Cong | N23: District | O23: number of seket
F24: Circuits | G24: =ROWS(tblSeket[]) -> 84 | I24: Kâte | J24: =COUNTIFS(tblSeket[distName],I24) -> 8 | K24: =COUNTIFS(tblParish[disName],I24) -> 59 | L24: =COUNTIFS(tblCong[distName],I24) -> 283 | N24: Kâte | O24: 8
F25: Parishes | G25: =ROWS(tblParish[]) -> 355 | I25: Jabem | J25: =COUNTIFS(tblSeket[distName],I25) -> 14 | K25: =COUNTIFS(tblParish[disName],I25) -> 116 | L25: =COUNTIFS(tblCong[distName],I25) -> 542 | N25: Jabem | O25: 14
F26: Congregations | G26: =ROWS(tblCong[]) -> 1395 | I26: Madang | J26: =COUNTIFS(tblSeket[distName],I26) -> 8 | K26: =COUNTIFS(tblParish[disName],I26) -> 33 | L26: =COUNTIFS(tblCong[distName],I26) -> 70 | N26: Madang | O26: 8
I27: Karkar | J27: =COUNTIFS(tblSeket[distName],I27) -> 6 | K27: =COUNTIFS(tblParish[disName],I27) -> 31 | L27: =COUNTIFS(tblCong[distName],I27) -> 71 | N27: Karkar | O27: 6
I28: Siassi | J28: =COUNTIFS(tblSeket[distName],I28) -> 2 | K28: =COUNTIFS(tblParish[disName],I28) -> 15 | L28: =COUNTIFS(tblCong[distName],I28) -> 35 | N28: Siassi | O28: 2
I29: Ukata | J29: =COUNTIFS(tblSeket[distName],I29) -> 10 | K29: 57 | L29: 253 | N29: Boana | O29: 3
I30: Boana | J30: =COUNTIFS(tblSeket[distName],I30) -> 3 | K30: =COUNTIFS(tblParish[disName],I30) -> 18 | L30: =COUNTIFS(tblCong[distName],I30) -> 96 | N30: Mumeng | O30: 5
I31: Mumeng | J31: =COUNTIFS(tblSeket[distName],I31) -> 5 | K31: =COUNTIFS(tblParish[disName],I31) -> 19 | L31: =COUNTIFS(tblCong[distName],I31) -> 82 | N31: Ukata | O31: 10
I32: NGI | J32: =COUNTIFS(tblSeket[distName],I32) -> 4 | K32: =COUNTIFS(tblParish[disName],I32) -> 5 | L32: =COUNTIFS(tblCong[distName],I32) -> 9 | N32: NGI | O32: 4
I33: Papua | J33: 4 | K33: NA | L33: 30 | N33: Goroka | O33: 7
I34: Kainantu | J34: 7 | K34: 25 | L34: 104 | N34: Simbu | O34: 17
I35: Goroka | J35: =COUNTIFS(tblSeket[distName],I35) -> 7 | K35: =COUNTIFS(tblParish[disName],I35) -> 18 | L35: =COUNTIFS(tblCong[distName],I35) -> 36 | N35: Grand Total | O35: 84
I36: East Simbu | J36: 0 | K36: 0 | L36: 0
I37: Simbu | J37: =COUNTIFS(tblSeket[distName],I37) -> 17 | K37: 16 | L37: 250
I38: Jiwaka | J38: 8 | K38: 52 | L38: 205
I39: Hagen | J39: 13 | K39: 50 | L39: 242
I40: Emmanuel | J40: =COUNTIFS(tblSeket[distName],I40) -> 0 | K40: =COUNTIFS(tblParish[disName],I40) -> 0 | L40: =COUNTIFS(tblCong[distName],I40) -> 0
I42: total | J42: =SUM(J24:J40) -> 116 | K42: =SUM(K24:K40) -> 514 | L42: =SUM(L24:L40) -> 2308
F45: 4.List and number of congregation, per district, seket, parish | J45: 5. List and number of Parishes per district, seket
F47: Dist/Seket/Parish | G47: number of cong | J47: Districts | K47: number of Parish
F48: Kâte | G48: 283 | J48: Kâte | K48: 59
...

Sheet Distrik
E2: District Codes
F4: DistCode | G4: Dist Name
F5: D01 | G5: Kâte
F6: D02 | G6: Jabem
F7: D03 | G7: Madang
B8: =Dashboard!B8 -> District Code Records | F8: D04 | G8: Karkar
B9: =Dashboard!B9 -> as of March 2023 | F9: D05 | G9: Siassi
F10: D06 | G10: Ukata
F11: D07 | G11: Boana
B12: District | F12: D08 | G12: Mumeng
F13: D09 | G13: NGI
F14: D10 | G14: Papua
B15: Seket | F15: D11 | G15: Kainantu
F16: D12 | G16: Goroka
F17: D13 | G17: Is Simbu
B18: Parish | F18: D14 | G18: Simbu
F19: D15 | G19: Jiwaka
F20: D16 | G20: Hagen
B21: Congregation | F21: D17 | G21: Imanuel
B24: Summary

Sheet Seket
E2: Seket Codes
F3: Seket Information | I3: total rows | J3: =SUBTOTAL(3,tblSeket[SeketCode]) -> 84
F4: SeketCode | G4: DistCode | H4: distName | I4: scode | J4: SeketName
F5: =CONCATENATE(tblSeket[[#This Row],[DistCode]],"-",tblSeket[[#This Row],[scode]]) -> D01-S01 | G5: =Distrik!F5 -> D01 | H5: =VLOOKUP(tblSeket[[#This Row],[DistCode]],tblDistrict[#All],2,FALSE) -> Kâte | I5: S01 | J5: Kalasa
F6: =CONCATENATE(tblSeket[[#This Row],[DistCode]],"-",tblSeket[[#This Row],[scode]]) -> D01-S02 | G6: =Distrik!F5 -> D01 | H6: =VLOOKUP(tblSeket[[#This Row],[DistCode]],tblDistrict[#All],2,FALSE) -> Kâte | I6: S02 | J6: Dedua
F7: =CONCATENATE(tblSeket[[#This Row],[DistCode]],"-",tblSeket[[#This Row],[scode]]) -> D01-S03 | G7: =Distrik!F5 -> D01 | H7: =VLOOKUP(tblSeket[[#This Row],[DistCode]],tblDistrict[#All],2,FALSE) -> Kâte | I7: S03 | J7: Sattelberg
B8: =Dashboard!B8 -> District Code Records | F8: =CONCATENATE(tblSeket[[#This Row],[DistCode]],"-",tblSeket[[#This Row],[scode]]) -> D01-S04 | G8: =Distrik!F5 -> D01 | H8: =VLOOKUP(tblSeket[[#This Row],[DistCode]],tblDistrict[#All],2,FALSE) -> Kâte | I8: S04 | J8: Qembung
B9: =Dashboard!B9 -> as of March 2023 | F9: =CONCATENATE(tblSeket[[#This Row],[DistCode]],"-",tblSeket[[#This Row],[scode]]) -> D01-S05 | G9: =Distrik!F5 -> D01 | H9: =VLOOKUP(tblSeket[[#This Row],[DistCode]],tblDistrict[#All],2,FALSE) -> Kâte | I9: S05 | J9: Hube
F10: =CONCATENATE(tblSeket[[#This Row],[DistCode]],"-",tblSeket[[#This Row],[scode]]) -> D01-S06 | G10: =Distrik!F5 -> D01 | H10: =VLOOKUP(tblSeket[[#This Row],[DistCode]],tblDistrict[#All],2,FALSE) -> Kâte | I10: S06 | J10: Somba
F11: =CONCATENATE(tblSeket[[#This Row],[DistCode]],"-",tblSeket[[#This Row],[scode]]) -> D01-S07 | G11: =Distrik!F5 -> D01 | H11: =VLOOKUP(tblSeket[[#This Row],[DistCode]],tblDistrict[#All],2,FALSE) -> Kâte | I11: S07 | J11: Zaka
B12: District | F12: =CONCATENATE(tblSeket[[#This Row],[DistCode]],"-",tblSeket[[#This Row],[scode]]) -> D01-S08 | G12: =Distrik!F5 -> D01 | H12: =VLOOKUP(tblSeket[[#This Row],[DistCode]],tblDistrict[#All],2,FALSE) -> Kâte | I12: S08 | J12: Garaina
F13: =CONCATENATE(tblSeket[[#This Row],[DistCode]],"-",tblSeket[[#This Row],[scode]]) -> D02-S01 | G13: =Distrik!F6 -> D02 | H13: =VLOOKUP(tblSeket[[#This Row],[DistCode]],tblDistrict[#All],2,FALSE) -> Jabem | I13: S01 | J13: Aseki
F14: =CONCATENATE(tblSeket[[#This Row],[DistCode]],"-",tblSeket[[#This Row],[scode]]) -> D02-S02 | G14: =Distrik!F6 -> D02 | H14: =VLOOKUP(tblSeket[[#This Row],[DistCode]],tblDistrict[#All],2,FALSE) -> Jabem | I14: S02 | J14: Deka
B15: Seket | F15: =CONCATENATE(tblSeket[[#This Row],[DistCode]],"-",tblSeket[[#This Row],[scode]]) -> D02-S03 | G15: =Distrik!F6 -> D02 | H15: =VLOOKUP(tblSeket[[#This Row],[DistCode]],tblDistrict[#All],2,FALSE) -> Jabem | I15: S03 | J15: Buang
F16: =CONCATENATE(tblSeket[[#This Row],[DistCode]],"-",tblSeket[[#This Row],[scode]]) -> D02-S04 | G16: =Distrik!F6 -> D02 | H16: =VLOOKUP(tblSeket[[#This Row],[DistCode]],tblDistrict[#All],2,FALSE) -> Jabem | I16: S04 | J16: Kaiapit
F17: =CONCATENATE(tblSeket[[#This Row],[DistCode]],"-",tblSeket[[#This Row],[scode]]) -> D02-S05 | G17: =Distrik!F6 -> D02 | H17: =VLOOKUP(tblSeket[[#This Row],[DistCode]],tblDistrict[#All],2,FALSE) -> Jabem | I17: S05 | J17: Kainantiba
B18: Parish | F18: =CONCATENATE(tblSeket[[#This Row],[DistCode]],"-",tblSeket[[#This Row],[scode]]) -> D02-S06 | G18: =Distrik!F6 -> D02 | H18: =VLOOKUP(tblSeket[[#This Row],[DistCode]],tblDistrict[#All],2,FALSE) -> Jabem | I18: S06 | J18: Lae City
F19: =CONCATENATE(tblSeket[[#This Row],[DistCode]],"-",tblSeket[[#This Row],[scode]]) -> D02-S07 | G19: =Distrik!F6 -> D02 | H19: =VLOOKUP(tblSeket[[#This Row],[DistCode]],tblDistrict[#All],2,FALSE) -> Jabem | I19: S07 | J19: Lae
F20: =CONCATENATE(tblSeket[[#This Row],[DistCode]],"-",tblSeket[[#This Row],[scode]]) -> D02-S08 | G20: =Distrik!F6 -> D02 | H20: =VLOOKUP(tblSeket[[#This Row],[DistCode]],tblDistrict[#All],2,FALSE) -> Jabem | I20: S08 | J20: Laulu
B21: Congregation | F21: =CONCATENATE(tblSeket[[#This Row],[DistCode]],"-",tblSeket[[#This Row],[scode]]) -> D02-S09 | G21: =Distrik!F6 -> D02 | H21: =VLOOKUP(tblSeket[[#This Row],[DistCode]],tblDistrict[#All],2,FALSE) -> Jabem | I21: S09 | J21: Malalo
F22: =CONCATENATE(tblSeket[[#This Row],[DistCode]],"-",tblSeket[[#This Row],[scode]]) -> D02-S10 | G22: =Distrik!F6 -> D02 | H22: =VLOOKUP(tblSeket[[#This Row],[DistCode]],tblDistrict[#All],2,FALSE) -> Jabem | I22: S10 | J22: Menyamya
F23: =CONCATENATE(tblSeket[[#This Row],[DistCode]],"-",tblSeket[[#This Row],[scode]]) -> D02-S11 | G23: =Distrik!F6 -> D02 | H23: =VLOOKUP(tblSeket[[#This Row],[DistCode]],tblDistrict[#All],2,FALSE) -> Jabem | I23: S11 | J23: Sangang
B24: Summary | F24: =CONCATENATE(tblSeket[[#This Row],[DistCode]],"-",tblSeket[[#This Row],[scode]]) -> D02-S12 | G24: =Distrik!F6 -> D02 | H24: =VLOOKUP(tblSeket[[#This Row],[DistCode]],tblDistrict[#All],2,FALSE) -> Jabem | I24: S12 | J24: Wampar
F25: =CONCATENATE(tblSeket[[#This Row],[DistCode]],"-",tblSeket[[#This Row],[scode]]) -> D02-S13 | G25: =Distrik!F6 -> D02 | H25: =VLOOKUP(tblSeket[[#This Row],[DistCode]],tblDistrict[#All],2,FALSE) -> Jabem | I25: S13 | J25: Wantoat
F26: =CONCATENATE(tblSeket[[#This Row],[DistCode]],"-",tblSeket[[#This Row],[scode]]) -> D02-S14 | G26: =Distrik!F6 -> D02 | H26: =VLOOKUP(tblSeket[[#This Row],[DistCode]],tblDistrict[#All],2,FALSE) -> Jabem | I26: S14 | J26: Jabem
F27: =CONCATENATE(tblSeket[[#This Row],[DistCode]],"-",tblSeket[[#This Row],[scode]]) -> D03-S01 | G27: =Distrik!F7 -> D03 | H27: =VLOOKUP(tblSeket[[#This Row],[DistCode]],tblDistrict[#All],2,FALSE) -> Madang | I27: S01 | J27: Amele
F28: =CONCATENATE(tblSeket[[#This Row],[DistCode]],"-",tblSeket[[#This Row],[scode]]) -> D03-S02 | G28: =Distrik!F7 -> D03 | H28: =VLOOKUP(tblSeket[[#This Row],[DistCode]],tblDistrict[#All],2,FALSE) -> Madang | I28: S02 | J28: Bongu
F29: =CONCATENATE(tblSeket[[#This Row],[DistCode]],"-",tblSeket[[#This Row],[scode]]) -> D03-S03 | G29: =Distrik!F7 -> D03 | H29: =VLOOKUP(tblSeket[[#This Row],[DistCode]],tblDistrict[#All],2,FALSE) -> Madang | I29: S03 | J29: Biliau
F30: =CONCATENATE(tblSeket[[#This Row],[DistCode]],"-",tblSeket[[#This Row],[scode]]) -> D03-S04 | G30: =Distrik!F7 -> D03 | H30: =VLOOKUP(tblSeket[[#This Row],[DistCode]],tblDistrict[#All],2,FALSE) -> Madang | I30: S04 | J30: Begesin
F31: =CONCATENATE(tblSeket[[#This Row],[DistCode]],"-",tblSeket[[#This Row],[scode]]) -> D03-S05 | G31: =Distrik!F7 -> D03 | H31: =VLOOKUP(tblSeket[[#This Row],[DistCode]],tblDistrict[#All],2,FALSE) -> Madang | I31: S05 | J31: Kabak
F32: =CONCATENATE(tblSeket[[#This Row],[DistCode]],"-",tblSeket[[#This Row],[scode]]) -> D03-S06 | G32: =Distrik!F7 -> D03 | H32: =VLOOKUP(tblSeket[[#This Row],[DistCode]],tblDistrict[#All],2,FALSE) -> Madang | I32: S06 | J32: Ranara
F33: =CONCATENATE(tblSeket[[#This Row],[DistCode]],"-",tblSeket[[#This Row],[scode]]) -> D03-S07 | G33: =Distrik!F7 -> D03 | H33: =VLOOKUP(tblSeket[[#This Row],[DistCode]],tblDistrict[#All],2,FALSE) -> Madang | I33: S07 | J33: Madang Taun
F34: =CONCATENATE(tblSeket[[#This Row],[DistCode]],"-",tblSeket[[#This Row],[scode]]) -> D03-S08 | G34: =Distrik!F7 -> D03 | H34: =VLOOKUP(tblSeket[[#This Row],[DistCode]],tblDistrict[#All],2,FALSE) -> Madang | I34: S08 | J34: Wanuma
F35: =CONCATENATE(tblSeket[[#This Row],[DistCode]],"-",tblSeket[[#This Row],[scode]]) -> D04-S01 | G35: =Distrik!F8 -> D04 | H35: =VLOOKUP(tblSeket[[#This Row],[DistCode]],tblDistrict[#All],2,FALSE) -> Karkar | I35: S01 | J35: Samoan
F36: =CONCATENATE(tblSeket[[#This Row],[DistCode]],"-",tblSeket[[#This Row],[scode]]) -> D04-S02 | G36: =Distrik!F8 -> D04 | H36: =VLOOKUP(tblSeket[[#This Row],[DistCode]],tblDistrict[#All],2,FALSE) -> Karkar | I36: S02 | J36: Bumsol
F37: =CONCATENATE(tblSeket[[#This Row],[DistCode]],"-",tblSeket[[#This Row],[scode]]) -> D04-S03 | G37: =Distrik!F8 -> D04 | H37: =VLOOKUP(tblSeket[[#This Row],[DistCode]],tblDistrict[#All],2,FALSE) -> Karkar | I37: S03 | J37: Kulubob
F38: =CONCATENATE(tblSeket[[#This Row],[DistCode]],"-",tblSeket[[#This Row],[scode]]) -> D04-S04 | G38: =Distrik!F8 -> D04 | H38: =VLOOKUP(tblSeket[[#This Row],[DistCode]],tblDistrict[#All],2,FALSE) -> Karkar | I38: S04 | J38: Bagiai
F39: =CONCATENATE(tblSeket[[#This Row],[DistCode]],"-",tblSeket[[#This Row],[scode]]) -> D04-S05 | G39: =Distrik!F8 -> D04 | H39: =VLOOKUP(tblSeket[[#This Row],[DistCode]],tblDistrict[#All],2,FALSE) -> Karkar | I39: S05 | J39: Tagub
F40: =CONCATENATE(tblSeket[[#This Row],[DistCode]],"-",tblSeket[[#This Row],[scode]]) -> D04-S06 | G40: =Distrik!F8 -> D04 | H40: =VLOOKUP(tblSeket[[#This Row],[DistCode]],tblDistrict[#All],2,FALSE) -> Karkar | I40: S06 | J40: Bagabag
F41: =CONCATENATE(tblSeket[[#This Row],[DistCode]],"-",tblSeket[[#This Row],[scode]]) -> D05-S01 | G41: =Distrik!F9 -> D05 | H41: =VLOOKUP(tblSeket[[#This Row],[DistCode]],tblDistrict[#All],2,FALSE) -> Siassi | I41: S01 | J41: Zone 1: Molap
...

Sheet Paris
E2: Parish Codes
L3: total rows: | M3: =SUBTOTAL(3,tblParish[parishCode]) -> 354
F4: parishCode | G4: DistCode | H4: disName | I4: sCode | J4: seketCode | K4: seketName | L4: pCode | M4: Paris Name
F5: =CONCATENATE(tblParish[[#This Row],[seketCode]],"-",tblParish[[#This Row],[pCode]]) -> D01-S01-P01 | G5: =Distrik!F$5 -> D01 | H5: =VLOOKUP(tblParish[[#This Row],[DistCode]],tblDistrict[],2,FALSE) -> Kâte | I5: =Seket!I$5 -> S01 | J5: =CONCATENATE(tblParish[[#This Row],[DistCode]],"-",tblParish[[#This Row],[sCode]]) -> D01-S01 | K5: =VLOOKUP(tblParish[[#This Row],[seketCode]],tblSeket[#All],5,FALSE) -> Kalasa | L5: P01 | M5: Amugen
F6: =CONCATENATE(tblParish[[#This Row],[seketCode]],"-",tblParish[[#This Row],[pCode]]) -> D01-S01-P02 | G6: =Distrik!F$5 -> D01 | H6: =VLOOKUP(tblParish[[#This Row],[DistCode]],tblDistrict[],2,FALSE) -> Kâte | I6: =Seket!I$5 -> S01 | J6: =CONCATENATE(tblParish[[#This Row],[DistCode]],"-",tblParish[[#This Row],[sCode]]) -> D01-S01 | K6: =VLOOKUP(tblParish[[#This Row],[seketCode]],tblSeket,5,FALSE) -> #NAME? | L6: P02 | M6: Tigasu
F7: =CONCATENATE(tblParish[[#This Row],[seketCode]],"-",tblParish[[#This Row],[pCode]]) -> D01-S01-P03 | G7: =Distrik!F$5 -> D01 | H7: =VLOOKUP(tblParish[[#This Row],[DistCode]],tblDistrict[],2,FALSE) -> Kâte | I7: =Seket!I$5 -> S01 | J7: =CONCATENATE(tblParish[[#This Row],[DistCode]],"-",tblParish[[#This Row],[sCode]]) -> D01-S01 | K7: =VLOOKUP(tblParish[[#This Row],[seketCode]],tblSeket,5,FALSE) -> #NAME? | L7: P03 | M7: Kanome
B8: =Dashboard!B8 -> District Code Records | F8: =CONCATENATE(tblParish[[#This Row],[seketCode]],"-",tblParish[[#This Row],[pCode]]) -> D01-S01-P04 | G8: =Distrik!F$5 -> D01 | H8: =VLOOKUP(tblParish[[#This Row],[DistCode]],tblDistrict[],2,FALSE) -> Kâte | I8: =Seket!I$5 -> S01 | J8: =CONCATENATE(tblParish[[#This Row],[DistCode]],"-",tblParish[[#This Row],[sCode]]) -> D01-S01 | K8: =VLOOKUP(tblParish[[#This Row],[seketCode]],tblSeket,5,FALSE) -> #NAME? | L8: P04 | M8: Ririwo
B9: =Dashboard!B9 -> as of March 2023 | F9: =CONCATENATE(tblParish[[#This Row],[seketCode]],"-",tblParish[[#This Row],[pCode]]) -> D01-S01-P05 | G9: =Distrik!F$5 -> D01 | H9: =VLOOKUP(tblParish[[#This Row],[DistCode]],tblDistrict[],2,FALSE) -> Kâte | I9: =Seket!I$5 -> S01 | J9: =CONCATENATE(tblParish[[#This Row],[DistCode]],"-",tblParish[[#This Row],[sCode]]) -> D01-S01 | K9: =VLOOKUP(tblParish[[#This Row],[seketCode]],tblSeket,5,FALSE) -> #NAME? | L9: P05 | M9: Gegibo
F10: =CONCATENATE(tblParish[[#This Row],[seketCode]],"-",tblParish[[#This Row],[pCode]]) -> D01-S01-P06 | G10: =Distrik!F$5 -> D01 | H10: =VLOOKUP(tblParish[[#This Row],[DistCode]],tblDistrict[],2,FALSE) -> Kâte | I10: =Seket!I$5 -> S01 | J10: =CONCATENATE(tblParish[[#This Row],[DistCode]],"-",tblParish[[#This Row],[sCode]]) -> D01-S01 | K10: =VLOOKUP(tblParish[[#This Row],[seketCode]],tblSeket,5,FALSE) -> #NAME? | L10: P06 | M10: Gitukia
F11: =CONCATENATE(tblParish[[#This Row],[seketCode]],"-",tblParish[[#This Row],[pCode]]) -> D01-S01-P07 | G11: =Distrik!F$5 -> D01 | H11: =VLOOKUP(tblParish[[#This Row],[DistCode]],tblDistrict[],2,FALSE) -> Kâte | I11: =Seket!I$5 -> S01 | J11: =CONCATENATE(tblParish[[#This Row],[DistCode]],"-",tblParish[[#This Row],[sCode]]) -> D01-S01 | K11: =VLOOKUP(tblParish[[#This Row],[seketCode]],tblSeket,5,FALSE) -> #NAME? | L11: P07 | M11: Botara
B12: District | F12: =CONCATENATE(tblParish[[#This Row],[seketCode]],"-",tblParish[[#This Row],[pCode]]) -> D01-S01-P08 | G12: =Distrik!F$5 -> D01 | H12: =VLOOKUP(tblParish[[#This Row],[DistCode]],tblDistrict[],2,FALSE) -> Kâte | I12: =Seket!I$5 -> S01 | J12: =CONCATENATE(tblParish[[#This Row],[DistCode]],"-",tblParish[[#This Row],[sCode]]) -> D01-S01 | K12: =VLOOKUP(tblParish[[#This Row],[seketCode]],tblSeket,5,FALSE) -> #NAME? | L12: P08 | M12: Tibaki
F13: =CONCATENATE(tblParish[[#This Row],[seketCode]],"-",tblParish[[#This Row],[pCode]]) -> D01-S02-P01 | G13: =Distrik!F$5 -> D01 | H13: =VLOOKUP(tblParish[[#This Row],[DistCode]],tblDistrict[],2,FALSE) -> Kâte | I13: =Seket!I$6 -> S02 | J13: =CONCATENATE(tblParish[[#This Row],[DistCode]],"-",tblParish[[#This Row],[sCode]]) -> D01-S02 | K13: =VLOOKUP(tblParish[[#This Row],[seketCode]],tblSeket,5,FALSE) -> #NAME? | L13: P01 | M13: Yumeng
F14: =CONCATENATE(tblParish[[#This Row],[seketCode]],"-",tblParish[[#This Row],[pCode]]) -> D01-S02-P02 | G14: =Distrik!F$5 -> D01 | H14: =VLOOKUP(tblParish[[#This Row],[DistCode]],tblDistrict[],2,FALSE) -> Kâte | I14: =Seket!I$6 -> S02 | J14: =CONCATENATE(tblParish[[#This Row],[DistCode]],"-",tblParish[[#This Row],[sCode]]) -> D01-S02 | K14: =VLOOKUP(tblParish[[#This Row],[seketCode]],tblSeket,5,FALSE) -> #NAME? | L14: P02 | M14: Munsel
B15: Seket | F15: =CONCATENATE(tblParish[[#This Row],[seketCode]],"-",tblParish[[#This Row],[pCode]]) -> D01-S02-P03 | G15: =Distrik!F$5 -> D01 | H15: =VLOOKUP(tblParish[[#This Row],[DistCode]],tblDistrict[],2,FALSE) -> Kâte | I15: =Seket!I$6 -> S02 | J15: =CONCATENATE(tblParish[[#This Row],[DistCode]],"-",tblParish[[#This Row],[sCode]]) -> D01-S02 | K15: =VLOOKUP(tblParish[[#This Row],[seketCode]],tblSeket,5,FALSE) -> #NAME? | L15: P03 | M15: Masa
F16: =CONCATENATE(tblParish[[#This Row],[seketCode]],"-",tblParish[[#This Row],[pCode]]) -> D01-S02-P04 | G16: =Distrik!F$5 -> D01 | H16: =VLOOKUP(tblParish[[#This Row],[DistCode]],tblDistrict[],2,FALSE) -> Kâte | I16: =Seket!I$6 -> S02 | J16: =CONCATENATE(tblParish[[#This Row],[DistCode]],"-",tblParish[[#This Row],[sCode]]) -> D01-S02 | K16: =VLOOKUP(tblParish[[#This Row],[seketCode]],tblSeket,5,FALSE) -> #NAME? | L16: P04 | M16: Yasire
F17: =CONCATENATE(tblParish[[#This Row],[seketCode]],"-",tblParish[[#This Row],[pCode]]) -> D01-S02-P05 | G17: =Distrik!F$5 -> D01 | H17: =VLOOKUP(tblParish[[#This Row],[DistCode]],tblDistrict[],2,FALSE) -> Kâte | I17: =Seket!I$6 -> S02 | J17: =CONCATENATE(tblParish[[#This Row],[DistCode]],"-",tblParish[[#This Row],[sCode]]) -> D01-S02 | K17: =VLOOKUP(tblParish[[#This Row],[seketCode]],tblSeket,5,FALSE) -> #NAME? | L17: P05 | M17: Koyoza
B18: Parish | F18: =CONCATENATE(tblParish[[#This Row],[seketCode]],"-",tblParish[[#This Row],[pCode]]) -> D01-S02-P06 | G18: =Distrik!F$5 -> D01 | H18: =VLOOKUP(tblParish[[#This Row],[DistCode]],tblDistrict[],2,FALSE) -> Kâte | I18: =Seket!I$6 -> S02 | J18: =CONCATENATE(tblParish[[#This Row],[DistCode]],"-",tblParish[[#This Row],[sCode]]) -> D01-S02 | K18: =VLOOKUP(tblParish[[#This Row],[seketCode]],tblSeket,5,FALSE) -> #NAME? | L18: P06 | M18: Zazozo
F19: =CONCATENATE(tblParish[[#This Row],[seketCode]],"-",tblParish[[#This Row],[pCode]]) -> D01-S02-P07 | G19: =Distrik!F$5 -> D01 | H19: =VLOOKUP(tblParish[[#This Row],[DistCode]],tblDistrict[],2,FALSE) -> Kâte | I19: =Seket!I$6 -> S02 | J19: =CONCATENATE(tblParish[[#This Row],[DistCode]],"-",tblParish[[#This Row],[sCode]]) -> D01-S02 | K19: =VLOOKUP(tblParish[[#This Row],[seketCode]],tblSeket,5,FALSE) -> #NAME? | L19: P07 | M19: Huwago
F20: =CONCATENATE(tblParish[[#This Row],[seketCode]],"-",tblParish[[#This Row],[pCode]]) -> D01-S03-P01 | G20: =Distrik!F$5 -> D01 | H20: =VLOOKUP(tblParish[[#This Row],[DistCode]],tblDistrict[],2,FALSE) -> Kâte | I20: =Seket!I$7 -> S03 | J20: =CONCATENATE(tblParish[[#This Row],[DistCode]],"-",tblParish[[#This Row],[sCode]]) -> D01-S03 | K20: =VLOOKUP(tblParish[[#This Row],[seketCode]],tblSeket,5,FALSE) -> #NAME? | L20: P01 | M20: Efa
B21: Congregation | F21: =CONCATENATE(tblParish[[#This Row],[seketCode]],"-",tblParish[[#This Row],[pCode]]) -> D01-S03-P02 | G21: =Distrik!F$5 -> D01 | H21: =VLOOKUP(tblParish[[#This Row],[DistCode]],tblDistrict[],2,FALSE) -> Kâte | I21: =Seket!I$7 -> S03 | J21: =CONCATENATE(tblParish[[#This Row],[DistCode]],"-",tblParish[[#This Row],[sCode]]) -> D01-S03 | K21: =VLOOKUP(tblParish[[#This Row],[seketCode]],tblSeket,5,FALSE) -> #NAME? | L21: P02 | M21: Bomaza
F22: =CONCATENATE(tblParish[[#This Row],[seketCode]],"-",tblParish[[#This Row],[pCode]]) -> D01-S03-P03 | G22: =Distrik!F$5 -> D01 | H22: =VLOOKUP(tblParish[[#This Row],[DistCode]],tblDistrict[],2,FALSE) -> Kâte | I22: =Seket!I$7 -> S03 | J22: =CONCATENATE(tblParish[[#This Row],[DistCode]],"-",tblParish[[#This Row],[sCode]]) -> D01-S03 | K22: =VLOOKUP(tblParish[[#This Row],[seketCode]],tblSeket,5,FALSE) -> #NAME? | L22: P03 | M22: Zukiba
F23: =CONCATENATE(tblParish[[#This Row],[seketCode]],"-",tblParish[[#This Row],[pCode]]) -> D01-S03-P04 | G23: =Distrik!F$5 -> D01 | H23: =VLOOKUP(tblParish[[#This Row],[DistCode]],tblDistrict[],2,FALSE) -> Kâte | I23: =Seket!I$7 -> S03 | J23: =CONCATENATE(tblParish[[#This Row],[DistCode]],"-",tblParish[[#This Row],[sCode]]) -> D01-S03 | K23: =VLOOKUP(tblParish[[#This Row],[seketCode]],tblSeket,5,FALSE) -> #NAME? | L23: P04 | M23: Fosama
B24: Summary | F24: =CONCATENATE(tblParish[[#This Row],[seketCode]],"-",tblParish[[#This Row],[pCode]]) -> D01-S03-P05 | G24: =Distrik!F$5 -> D01 | H24: =VLOOKUP(tblParish[[#This Row],[DistCode]],tblDistrict[],2,FALSE) -> Kâte | I24: =Seket!I$7 -> S03 | J24: =CONCATENATE(tblParish[[#This Row],[DistCode]],"-",tblParish[[#This Row],[sCode]]) -> D01-S03 | K24: =VLOOKUP(tblParish[[#This Row],[seketCode]],tblSeket,5,FALSE) -> #NAME? | L24: P05 | M24: Agororo
F25: =CONCATENATE(tblParish[[#This Row],[seketCode]],"-",tblParish[[#This Row],[pCode]]) -> D01-S03-P06 | G25: =Distrik!F$5 -> D01 | H25: =VLOOKUP(tblParish[[#This Row],[DistCode]],tblDistrict[],2,FALSE) -> Kâte | I25: =Seket!I$7 -> S03 | J25: =CONCATENATE(tblParish[[#This Row],[DistCode]],"-",tblParish[[#This Row],[sCode]]) -> D01-S03 | K25: =VLOOKUP(tblParish[[#This Row],[seketCode]],tblSeket,5,FALSE) -> #NAME? | L25: P06 | M25: Sasibona
F26: =CONCATENATE(tblParish[[#This Row],[seketCode]],"-",tblParish[[#This Row],[pCode]]) -> D01-S03-P07 | G26: =Distrik!F$5 -> D01 | H26: =VLOOKUP(tblParish[[#This Row],[DistCode]],tblDistrict[],2,FALSE) -> Kâte | I26: =Seket!I$7 -> S03 | J26: =CONCATENATE(tblParish[[#This Row],[DistCode]],"-",tblParish[[#This Row],[sCode]]) -> D01-S03 | K26: =VLOOKUP(tblParish[[#This Row],[seketCode]],tblSeket,5,FALSE) -> #NAME? | L26: P07 | M26: Wemo
F27: =CONCATENATE(tblParish[[#This Row],[seketCode]],"-",tblParish[[#This Row],[pCode]]) -> D01-S03-P08 | G27: =Distrik!F$5 -> D01 | H27: =VLOOKUP(tblParish[[#This Row],[DistCode]],tblDistrict[],2,FALSE) -> Kâte | I27: =Seket!I$7 -> S03 | J27: =CONCATENATE(tblParish[[#This Row],[DistCode]],"-",tblParish[[#This Row],[sCode]]) -> D01-S03 | K27: =VLOOKUP(tblParish[[#This Row],[seketCode]],tblSeket,5,FALSE) -> #NAME? | L27: P08 | M27: Kitaka
F28: =CONCATENATE(tblParish[[#This Row],[seketCode]],"-",tblParish[[#This Row],[pCode]]) -> D01-S03-P09 | G28: =Distrik!F$5 -> D01 | H28: =VLOOKUP(tblParish[[#This Row],[DistCode]],tblDistrict[],2,FALSE) -> Kâte | I28: =Seket!I$7 -> S03 | J28: =CONCATENATE(tblParish[[#This Row],[DistCode]],"-",tblParish[[#This Row],[sCode]]) -> D01-S03 | K28: =VLOOKUP(tblParish[[#This Row],[seketCode]],tblSeket,5,FALSE) -> #NAME? | L28: P09 | M28: Keregia
F29: =CONCATENATE(tblParish[[#This Row],[seketCode]],"-",tblParish[[#This Row],[pCode]]) -> D01-S03-P10 | G29: =Distrik!F$5 -> D01 | H29: =VLOOKUP(tblParish[[#This Row],[DistCode]],tblDistrict[],2,FALSE) -> Kâte | I29: =Seket!I$7 -> S03 | J29: =CONCATENATE(tblParish[[#This Row],[DistCode]],"-",tblParish[[#This Row],[sCode]]) -> D01-S03 | K29: =VLOOKUP(tblParish[[#This Row],[seketCode]],tblSeket,5,FALSE) -> #NAME? | L29: P10 | M29: Wandokai
F30: =CONCATENATE(tblParish[[#This Row],[seketCode]],"-",tblParish[[#This Row],[pCode]]) -> D01-S03-P11 | G30: =Distrik!F$5 -> D01 | H30: =VLOOKUP(tblParish[[#This Row],[DistCode]],tblDistrict[],2,FALSE) -> Kâte | I30: =Seket!I$7 -> S03 | J30: =CONCATENATE(tblParish[[#This Row],[DistCode]],"-",tblParish[[#This Row],[sCode]]) -> D01-S03 | K30: =VLOOKUP(tblParish[[#This Row],[seketCode]],tblSeket,5,FALSE) -> #NAME? | L30: P11 | M30: Wareo
F31: =CONCATENATE(tblParish[[#This Row],[seketCode]],"-",tblParish[[#This Row],[pCode]]) -> D01-S03-P12 | G31: =Distrik!F$5 -> D01 | H31: =VLOOKUP(tblParish[[#This Row],[DistCode]],tblDistrict[],2,FALSE) -> Kâte | I31: =Seket!I$7 -> S03 | J31: =CONCATENATE(tblParish[[#This Row],[DistCode]],"-",tblParish[[#This Row],[sCode]]) -> D01-S03 | K31: =VLOOKUP(tblParish[[#This Row],[seketCode]],tblSeket,5,FALSE) -> #NAME? | L31: P12 | M31: Zamesa
F32: =CONCATENATE(tblParish[[#This Row],[seketCode]],"-",tblParish[[#This Row],[pCode]]) -> D01-S04-P01 | G32: =Distrik!F$5 -> D01 | H32: =VLOOKUP(tblParish[[#This Row],[DistCode]],tblDistrict[],2,FALSE) -> Kâte | I32: =Seket!I$8 -> S04 | J32: =CONCATENATE(tblParish[[#This Row],[DistCode]],"-",tblParish[[#This Row],[sCode]]) -> D01-S04 | K32: =VLOOKUP(tblParish[[#This Row],[seketCode]],tblSeket,5,FALSE) -> #NAME? | L32: P01 | M32: Guramoti
F33: =CONCATENATE(tblParish[[#This Row],[seketCode]],"-",tblParish[[#This Row],[pCode]]) -> D01-S04-P02 | G33: =Distrik!F$5 -> D01 | H33: =VLOOKUP(tblParish[[#This Row],[DistCode]],tblDistrict[],2,FALSE) -> Kâte | I33: =Seket!I$8 -> S04 | J33: =CONCATENATE(tblParish[[#This Row],[DistCode]],"-",tblParish[[#This Row],[sCode]]) -> D01-S04 | K33: =VLOOKUP(tblParish[[#This Row],[seketCode]],tblSeket,5,FALSE) -> #NAME? | L33: P02 | M33: Hamaka
F34: =CONCATENATE(tblParish[[#This Row],[seketCode]],"-",tblParish[[#This Row],[pCode]]) -> D01-S04-P03 | G34: =Distrik!F$5 -> D01 | H34: =VLOOKUP(tblParish[[#This Row],[DistCode]],tblDistrict[],2,FALSE) -> Kâte | I34: =Seket!I$8 -> S04 | J34: =CONCATENATE(tblParish[[#This Row],[DistCode]],"-",tblParish[[#This Row],[sCode]]) -> D01-S04 | K34: =VLOOKUP(tblParish[[#This Row],[seketCode]],tblSeket,5,FALSE) -> #NAME? | L34: P03 | M34: Babuso
F35: =CONCATENATE(tblParish[[#This Row],[seketCode]],"-",tblParish[[#This Row],[pCode]]) -> D01-S05-P01 | G35: =Distrik!F$5 -> D01 | H35: =VLOOKUP(tblParish[[#This Row],[DistCode]],tblDistrict[],2,FALSE) -> Kâte | I35: =Seket!I$9 -> S05 | J35: =CONCATENATE(tblParish[[#This Row],[DistCode]],"-",tblParish[[#This Row],[sCode]]) -> D01-S05 | K35: =VLOOKUP(tblParish[[#This Row],[seketCode]],tblSeket,5,FALSE) -> #NAME? | L35: P01 | M35: Kulungtufu
F36: =CONCATENATE(tblParish[[#This Row],[seketCode]],"-",tblParish[[#This Row],[pCode]]) -> D01-S05-P02 | G36: =Distrik!F$5 -> D01 | H36: =VLOOKUP(tblParish[[#This Row],[DistCode]],tblDistrict[],2,FALSE) -> Kâte | I36: =Seket!I$9 -> S05 | J36: =CONCATENATE(tblParish[[#This Row],[DistCode]],"-",tblParish[[#This Row],[sCode]]) -> D01-S05 | K36: =VLOOKUP(tblParish[[#This Row],[seketCode]],tblSeket,5,FALSE) -> #NAME? | L36: P02 | M36: Joangeng
F37: =CONCATENATE(tblParish[[#This Row],[seketCode]],"-",tblParish[[#This Row],[pCode]]) -> D01-S05-P03 | G37: =Distrik!F$5 -> D01 | H37: =VLOOKUP(tblParish[[#This Row],[DistCode]],tblDistrict[],2,FALSE) -> Kâte | I37: =Seket!I$9 -> S05 | J37: =CONCATENATE(tblParish[[#This Row],[DistCode]],"-",tblParish[[#This Row],[sCode]]) -> D01-S05 | K37: =VLOOKUP(tblParish[[#This Row],[seketCode]],tblSeket,5,FALSE) -> #NAME? | L37: P03 | M37: Kuma
F38: =CONCATENATE(tblParish[[#This Row],[seketCode]],"-",tblParish[[#This Row],[pCode]]) -> D01-S05-P04 | G38: =Distrik!F$5 -> D01 | H38: =VLOOKUP(tblParish[[#This Row],[DistCode]],tblDistrict[],2,FALSE) -> Kâte | I38: =Seket!I$9 -> S05 | J38: =CONCATENATE(tblParish[[#This Row],[DistCode]],"-",tblParish[[#This Row],[sCode]]) -> D01-S05 | K38: =VLOOKUP(tblParish[[#This Row],[seketCode]],tblSeket,5,FALSE) -> #NAME? | L38: P04 | M38: Dopi
F39: =CONCATENATE(tblParish[[#This Row],[seketCode]],"-",tblParish[[#This Row],[pCode]]) -> D01-S05-P05 | G39: =Distrik!F$5 -> D01 | H39: =VLOOKUP(tblParish[[#This Row],[DistCode]],tblDistrict[],2,FALSE) -> Kâte | I39: =Seket!I$9 -> S05 | J39: =CONCATENATE(tblParish[[#This Row],[DistCode]],"-",tblParish[[#This Row],[sCode]]) -> D01-S05 | K39: =VLOOKUP(tblParish[[#This Row],[seketCode]],tblSeket,5,FALSE) -> #NAME? | L39: P05 | M39: Foria
F40: =CONCATENATE(tblParish[[#This Row],[seketCode]],"-",tblParish[[#This Row],[pCode]]) -> D01-S05-P06 | G40: =Distrik!F$5 -> D01 | H40: =VLOOKUP(tblParish[[#This Row],[DistCode]],tblDistrict[],2,FALSE) -> Kâte | I40: =Seket!I$9 -> S05 | J40: =CONCATENATE(tblParish[[#This Row],[DistCode]],"-",tblParish[[#This Row],[sCode]]) -> D01-S05 | K40: =VLOOKUP(tblParish[[#This Row],[seketCode]],tblSeket,5,FALSE) -> #NAME? | L40: P06 | M40: Ebabang
F41: =CONCATENATE(tblParish[[#This Row],[seketCode]],"-",tblParish[[#This Row],[pCode]]) -> D01-S05-P07 | G41: =Distrik!F$5 -> D01 | H41: =VLOOKUP(tblParish[[#This Row],[DistCode]],tblDistrict[],2,FALSE) -> Kâte | I41: =Seket!I$9 -> S05 | J41: =CONCATENATE(tblParish[[#This Row],[DistCode]],"-",tblParish[[#This Row],[sCode]]) -> D01-S05 | K41: =VLOOKUP(tblParish[[#This Row],[seketCode]],tblSeket,5,FALSE) -> #NAME? | L41: P07 | M41: Jowacnuc
...

Sheet Kongrigesen
E2: Congregation Codes
O3: total rows: | P3: =SUBTOTAL(3,tblCong[congCode]) -> 1395
F4: congCode | G4: distCode | H4: distName | I4: sCode | J4: seketCode | K4: seketName | L4: pCode | M4: parishCode | N4: Paris Name | O4: kCode | P4: congName
F5: =CONCATENATE(tblCong[[#This Row],[parishCode]],"-",tblCong[[#This Row],[kCode]]) -> D01-S01-P01-K01 | G5: =Distrik!F$5 -> D01 | H5: =VLOOKUP(tblCong[[#This Row],[distCode]],tblDistrict[#All],2) -> Kâte | I5: =Seket!I$5 -> S01 | J5: =CONCATENATE(tblCong[[#This Row],[distCode]],"-",tblCong[[#This Row],[sCode]]) -> D01-S01 | K5: =VLOOKUP(tblCong[[#This Row],[seketCode]],tblSeket[#All],5,FALSE) -> Kalasa | L5: =Paris!L$5 -> P01 | M5: =CONCATENATE(tblCong[[#This Row],[seketCode]],"-",tblCong[[#This Row],[pCode]]) -> D01-S01-P01 | N5: =Paris!M$5 -> Amugen | O5: K01 | P5: Kip
F6: =CONCATENATE(tblCong[[#This Row],[parishCode]],"-",tblCong[[#This Row],[kCode]]) -> D01-S01-P01-K02 | G6: =Distrik!F$5 -> D01 | H6: =VLOOKUP(tblCong[[#This Row],[distCode]],tblDistrict[#All],2) -> Kâte | I6: =Seket!I$5 -> S01 | J6: =CONCATENATE(tblCong[[#This Row],[distCode]],"-",tblCong[[#This Row],[sCode]]) -> D01-S01 | K6: =VLOOKUP(tblCong[[#This Row],[seketCode]],tblSeket[#All],5,FALSE) -> Kalasa | L6: =Paris!L$5 -> P01 | M6: =CONCATENATE(tblCong[[#This Row],[seketCode]],"-",tblCong[[#This Row],[pCode]]) -> D01-S01-P01 | N6: =Paris!M$5 -> Amugen | O6: K02 | P6: Kukuya
F7: =CONCATENATE(tblCong[[#This Row],[parishCode]],"-",tblCong[[#This Row],[kCode]]) -> D01-S01-P01-K03 | G7: =Distrik!F$5 -> D01 | H7: =VLOOKUP(tblCong[[#This Row],[distCode]],tblDistrict[#All],2) -> Kâte | I7: =Seket!I$5 -> S01 | J7: =CONCATENATE(tblCong[[#This Row],[distCode]],"-",tblCong[[#This Row],[sCode]]) -> D01-S01 | K7: =VLOOKUP(tblCong[[#This Row],[seketCode]],tblSeket[#All],5,FALSE) -> Kalasa | L7: =Paris!L$5 -> P01 | M7: =CONCATENATE(tblCong[[#This Row],[seketCode]],"-",tblCong[[#This Row],[pCode]]) -> D01-S01-P01 | N7: =Paris!M$5 -> Amugen | O7: K03 | P7: Wetna
B8: =Dashboard!B8 -> District Code Records | F8: =CONCATENATE(tblCong[[#This Row],[parishCode]],"-",tblCong[[#This Row],[kCode]]) -> D01-S01-P01-K04 | G8: =Distrik!F$5 -> D01 | H8: =VLOOKUP(tblCong[[#This Row],[distCode]],tblDistrict[#All],2) -> Kâte | I8: =Seket!I$5 -> S01 | J8: =CONCATENATE(tblCong[[#This Row],[distCode]],"-",tblCong[[#This Row],[sCode]]) -> D01-S01 | K8: =VLOOKUP(tblCong[[#This Row],[seketCode]],tblSeket[#All],5,FALSE) -> Kalasa | L8: =Paris!L$5 -> P01 | M8: =CONCATENATE(tblCong[[#This Row],[seketCode]],"-",tblCong[[#This Row],[pCode]]) -> D01-S01-P01 | N8: =Paris!M$5 -> Amugen | O8: K04 | P8: Sikekea
B9: =Dashboard!B9 -> as of March 2023 | F9: =CONCATENATE(tblCong[[#This Row],[parishCode]],"-",tblCong[[#This Row],[kCode]]) -> D01-S01-P01-K05 | G9: =Distrik!F$5 -> D01 | H9: =VLOOKUP(tblCong[[#This Row],[distCode]],tblDistrict[#All],2) -> Kâte | I9: =Seket!I$5 -> S01 | J9: =CONCATENATE(tblCong[[#This Row],[distCode]],"-",tblCong[[#This Row],[sCode]]) -> D01-S01 | K9: =VLOOKUP(tblCong[[#This Row],[seketCode]],tblSeket[#All],5,FALSE) -> Kalasa | L9: =Paris!L$5 -> P01 | M9: =CONCATENATE(tblCong[[#This Row],[seketCode]],"-",tblCong[[#This Row],[pCode]]) -> D01-S01-P01 | N9: =Paris!M$5 -> Amugen | O9: K05 | P9: Kalasa
F10: =CONCATENATE(tblCong[[#This Row],[parishCode]],"-",tblCong[[#This Row],[kCode]]) -> D01-S01-P01-K06 | G10: =Distrik!F$5 -> D01 | H10: =VLOOKUP(tblCong[[#This Row],[distCode]],tblDistrict[#All],2) -> Kâte | I10: =Seket!I$5 -> S01 | J10: =CONCATENATE(tblCong[[#This Row],[distCode]],"-",tblCong[[#This Row],[sCode]]) -> D01-S01 | K10: =VLOOKUP(tblCong[[#This Row],[seketCode]],tblSeket[#All],5,FALSE) -> Kalasa | L10: =Paris!L$5 -> P01 | M10: =CONCATENATE(tblCong[[#This Row],[seketCode]],"-",tblCong[[#This Row],[pCode]]) -> D01-S01-P01 | N10: =Paris!M$5 -> Amugen | O10: K06 | P10: Orara
F11: =CONCATENATE(tblCong[[#This Row],[parishCode]],"-",tblCong[[#This Row],[kCode]]) -> D01-S01-P01-K07 | G11: =Distrik!F$5 -> D01 | H11: =VLOOKUP(tblCong[[#This Row],[distCode]],tblDistrict[#All],2) -> Kâte | I11: =Seket!I$5 -> S01 | J11: =CONCATENATE(tblCong[[#This Row],[distCode]],"-",tblCong[[#This Row],[sCode]]) -> D01-S01 | K11: =VLOOKUP(tblCong[[#This Row],[seketCode]],tblSeket[#All],5,FALSE) -> Kalasa | L11: =Paris!L$5 -> P01 | M11: =CONCATENATE(tblCong[[#This Row],[seketCode]],"-",tblCong[[#This Row],[pCode]]) -> D01-S01-P01 | N11: =Paris!M$5 -> Amugen | O11: K07 | P11: Betel
B12: District | F12: =CONCATENATE(tblCong[[#This Row],[parishCode]],"-",tblCong[[#This Row],[kCode]]) -> D01-S01-P02-K01 | G12: =Distrik!F$5 -> D01 | H12: =VLOOKUP(tblCong[[#This Row],[distCode]],tblDistrict[#All],2) -> Kâte | I12: =Seket!I$5 -> S01 | J12: =CONCATENATE(tblCong[[#This Row],[distCode]],"-",tblCong[[#This Row],[sCode]]) -> D01-S01 | K12: =VLOOKUP(tblCong[[#This Row],[seketCode]],tblSeket[#All],5,FALSE) -> Kalasa | L12: =Paris!L$6 -> P02 | M12: =CONCATENATE(tblCong[[#This Row],[seketCode]],"-",tblCong[[#This Row],[pCode]]) -> D01-S01-P02 | N12: =Paris!M$6 -> Tigasu | O12: K01 | P12: Sialum
F13: =CONCATENATE(tblCong[[#This Row],[parishCode]],"-",tblCong[[#This Row],[kCode]]) -> D01-S01-P02-K02 | G13: =Distrik!F$5 -> D01 | H13: =VLOOKUP(tblCong[[#This Row],[distCode]],tblDistrict[#All],2) -> Kâte | I13: =Seket!I$5 -> S01 | J13: =CONCATENATE(tblCong[[#This Row],[distCode]],"-",tblCong[[#This Row],[sCode]]) -> D01-S01 | K13: =VLOOKUP(tblCong[[#This Row],[seketCode]],tblSeket[#All],5,FALSE) -> Kalasa | L13: =Paris!L$6 -> P02 | M13: =CONCATENATE(tblCong[[#This Row],[seketCode]],"-",tblCong[[#This Row],[pCode]]) -> D01-S01-P02 | N13: =Paris!M$6 -> Tigasu | O13: K02 | P13: Nama
F14: =CONCATENATE(tblCong[[#This Row],[parishCode]],"-",tblCong[[#This Row],[kCode]]) -> D01-S01-P02-K03 | G14: =Distrik!F$5 -> D01 | H14: =VLOOKUP(tblCong[[#This Row],[distCode]],tblDistrict[#All],2) -> Kâte | I14: =Seket!I$5 -> S01 | J14: =CONCATENATE(tblCong[[#This Row],[distCode]],"-",tblCong[[#This Row],[sCode]]) -> D01-S01 | K14: =VLOOKUP(tblCong[[#This Row],[seketCode]],tblSeket[#All],5,FALSE) -> Kalasa | L14: =Paris!L$6 -> P02 | M14: =CONCATENATE(tblCong[[#This Row],[seketCode]],"-",tblCong[[#This Row],[pCode]]) -> D01-S01-P02 | N14: =Paris!M$6 -> Tigasu | O14: K03 | P14: Qambu
B15: Seket | F15: =CONCATENATE(tblCong[[#This Row],[parishCode]],"-",tblCong[[#This Row],[kCode]]) -> D01-S01-P02-K04 | G15: =Distrik!F$5 -> D01 | H15: =VLOOKUP(tblCong[[#This Row],[distCode]],tblDistrict[#All],2) -> Kâte | I15: =Seket!I$5 -> S01 | J15: =CONCATENATE(tblCong[[#This Row],[distCode]],"-",tblCong[[#This Row],[sCode]]) -> D01-S01 | K15: =VLOOKUP(tblCong[[#This Row],[seketCode]],tblSeket[#All],5,FALSE) -> Kalasa | L15: =Paris!L$6 -> P02 | M15: =CONCATENATE(tblCong[[#This Row],[seketCode]],"-",tblCong[[#This Row],[pCode]]) -> D01-S01-P02 | N15: =Paris!M$6 -> Tigasu | O15: K04 | P15: Romonga
F16: =CONCATENATE(tblCong[[#This Row],[parishCode]],"-",tblCong[[#This Row],[kCode]]) -> D01-S01-P02-K05 | G16: =Distrik!F$5 -> D01 | H16: =VLOOKUP(tblCong[[#This Row],[distCode]],tblDistrict[#All],2) -> Kâte | I16: =Seket!I$5 -> S01 | J16: =CONCATENATE(tblCong[[#This Row],[distCode]],"-",tblCong[[#This Row],[sCode]]) -> D01-S01 | K16: =VLOOKUP(tblCong[[#This Row],[seketCode]],tblSeket[#All],5,FALSE) -> Kalasa | L16: =Paris!L$6 -> P02 | M16: =CONCATENATE(tblCong[[#This Row],[seketCode]],"-",tblCong[[#This Row],[pCode]]) -> D01-S01-P02 | N16: =Paris!M$6 -> Tigasu | O16: K05 | P16: Station
F17: =CONCATENATE(tblCong[[#This Row],[parishCode]],"-",tblCong[[#This Row],[kCode]]) -> D01-S01-P03-K01 | G17: =Distrik!F$5 -> D01 | H17: =VLOOKUP(tblCong[[#This Row],[distCode]],tblDistrict[#All],2) -> Kâte | I17: =Seket!I$5 -> S01 | J17: =CONCATENATE(tblCong[[#This Row],[distCode]],"-",tblCong[[#This Row],[sCode]]) -> D01-S01 | K17: =VLOOKUP(tblCong[[#This Row],[seketCode]],tblSeket[#All],5,FALSE) -> Kalasa | L17: =Paris!L$7 -> P03 | M17: =CONCATENATE(tblCong[[#This Row],[seketCode]],"-",tblCong[[#This Row],[pCode]]) -> D01-S01-P03 | N17: =Paris!M$7 -> Kanome | O17: K01 | P17: Kanome
B18: Parish | F18: =CONCATENATE(tblCong[[#This Row],[parishCode]],"-",tblCong[[#This Row],[kCode]]) -> D01-S01-P03-K02 | G18: =Distrik!F$5 -> D01 | H18: =VLOOKUP(tblCong[[#This Row],[distCode]],tblDistrict[#All],2) -> Kâte | I18: =Seket!I$5 -> S01 | J18: =CONCATENATE(tblCong[[#This Row],[distCode]],"-",tblCong[[#This Row],[sCode]]) -> D01-S01 | K18: =VLOOKUP(tblCong[[#This Row],[seketCode]],tblSeket[#All],5,FALSE) -> Kalasa | L18: =Paris!L$7 -> P03 | M18: =CONCATENATE(tblCong[[#This Row],[seketCode]],"-",tblCong[[#This Row],[pCode]]) -> D01-S01-P03 | N18: =Paris!M$7 -> Kanome | O18: K02 | P18: Nada
F19: =CONCATENATE(tblCong[[#This Row],[parishCode]],"-",tblCong[[#This Row],[kCode]]) -> D01-S01-P03-K03 | G19: =Distrik!F$5 -> D01 | H19: =VLOOKUP(tblCong[[#This Row],[distCode]],tblDistrict[#All],2) -> Kâte | I19: =Seket!I$5 -> S01 | J19: =CONCATENATE(tblCong[[#This Row],[distCode]],"-",tblCong[[#This Row],[sCode]]) -> D01-S01 | K19: =VLOOKUP(tblCong[[#This Row],[seketCode]],tblSeket[#All],5,FALSE) -> Kalasa | L19: =Paris!L$7 -> P03 | M19: =CONCATENATE(tblCong[[#This Row],[seketCode]],"-",tblCong[[#This Row],[pCode]]) -> D01-S01-P03 | N19: =Paris!M$7 -> Kanome | O19: K03 | P19: Kanzarua
F20: =CONCATENATE(tblCong[[#This Row],[parishCode]],"-",tblCong[[#This Row],[kCode]]) -> D01-S01-P03-K04 | G20: =Distrik!F$5 -> D01 | H20: =VLOOKUP(tblCong[[#This Row],[distCode]],tblDistrict[#All],2) -> Kâte | I20: =Seket!I$5 -> S01 | J20: =CONCATENATE(tblCong[[#This Row],[distCode]],"-",tblCong[[#This Row],[sCode]]) -> D01-S01 | K20: =VLOOKUP(tblCong[[#This Row],[seketCode]],tblSeket[#All],5,FALSE) -> Kalasa | L20: =Paris!L$7 -> P03 | M20: =CONCATENATE(tblCong[[#This Row],[seketCode]],"-",tblCong[[#This Row],[pCode]]) -> D01-S01-P03 | N20: =Paris!M$7 -> Kanome | O20: K04 | P20: Marimari
B21: Congregation | F21: =CONCATENATE(tblCong[[#This Row],[parishCode]],"-",tblCong[[#This Row],[kCode]]) -> D01-S01-P04-K01 | G21: =Distrik!F$5 -> D01 | H21: =VLOOKUP(tblCong[[#This Row],[distCode]],tblDistrict[#All],2) -> Kâte | I21: =Seket!I$5 -> S01 | J21: =CONCATENATE(tblCong[[#This Row],[distCode]],"-",tblCong[[#This Row],[sCode]]) -> D01-S01 | K21: =VLOOKUP(tblCong[[#This Row],[seketCode]],tblSeket[#All],5,FALSE) -> Kalasa | L21: =Paris!L$8 -> P04 | M21: =CONCATENATE(tblCong[[#This Row],[seketCode]],"-",tblCong[[#This Row],[pCode]]) -> D01-S01-P04 | N21: =Paris!M$8 -> Ririwo | O21: K01 | P21: Ririwo
F22: =CONCATENATE(tblCong[[#This Row],[parishCode]],"-",tblCong[[#This Row],[kCode]]) -> D01-S01-P04-K02 | G22: =Distrik!F$5 -> D01 | H22: =VLOOKUP(tblCong[[#This Row],[distCode]],tblDistrict[#All],2) -> Kâte | I22: =Seket!I$5 -> S01 | J22: =CONCATENATE(tblCong[[#This Row],[distCode]],"-",tblCong[[#This Row],[sCode]]) -> D01-S01 | K22: =VLOOKUP(tblCong[[#This Row],[seketCode]],tblSeket[#All],5,FALSE) -> Kalasa | L22: =Paris!L$8 -> P04 | M22: =CONCATENATE(tblCong[[#This Row],[seketCode]],"-",tblCong[[#This Row],[pCode]]) -> D01-S01-P04 | N22: =Paris!M$8 -> Ririwo | O22: K02 | P22: Ga
F23: =CONCATENATE(tblCong[[#This Row],[parishCode]],"-",tblCong[[#This Row],[kCode]]) -> D01-S01-P04-K03 | G23: =Distrik!F$5 -> D01 | H23: =VLOOKUP(tblCong[[#This Row],[distCode]],tblDistrict[#All],2) -> Kâte | I23: =Seket!I$5 -> S01 | J23: =CONCATENATE(tblCong[[#This Row],[distCode]],"-",tblCong[[#This Row],[sCode]]) -> D01-S01 | K23: =VLOOKUP(tblCong[[#This Row],[seketCode]],tblSeket[#All],5,FALSE) -> Kalasa | L23: =Paris!L$8 -> P04 | M23: =CONCATENATE(tblCong[[#This Row],[seketCode]],"-",tblCong[[#This Row],[pCode]]) -> D01-S01-P04 | N23: =Paris!M$8 -> Ririwo | O23: K03 | P23: Sabe
B24: Summary | F24: =CONCATENATE(tblCong[[#This Row],[parishCode]],"-",tblCong[[#This Row],[kCode]]) -> D01-S01-P04-K04 | G24: =Distrik!F$5 -> D01 | H24: =VLOOKUP(tblCong[[#This Row],[distCode]],tblDistrict[#All],2) -> Kâte | I24: =Seket!I$5 -> S01 | J24: =CONCATENATE(tblCong[[#This Row],[distCode]],"-",tblCong[[#This Row],[sCode]]) -> D01-S01 | K24: =VLOOKUP(tblCong[[#This Row],[seketCode]],tblSeket[#All],5,FALSE) -> Kalasa | L24: =Paris!L$8 -> P04 | M24: =CONCATENATE(tblCong[[#This Row],[seketCode]],"-",tblCong[[#This Row],[pCode]]) -> D01-S01-P04 | N24: =Paris!M$8 -> Ririwo | O24: K04 | P24: Samep
F25: =CONCATENATE(tblCong[[#This Row],[parishCode]],"-",tblCong[[#This Row],[kCode]]) -> D01-S01-P05-K01 | G25: =Distrik!F$5 -> D01 | H25: =VLOOKUP(tblCong[[#This Row],[distCode]],tblDistrict[#All],2) -> Kâte | I25: =Seket!I$5 -> S01 | J25: =CONCATENATE(tblCong[[#This Row],[distCode]],"-",tblCong[[#This Row],[sCode]]) -> D01-S01 | K25: =VLOOKUP(tblCong[[#This Row],[seketCode]],tblSeket[#All],5,FALSE) -> Kalasa | L25: =Paris!L$9 -> P05 | M25: =CONCATENATE(tblCong[[#This Row],[seketCode]],"-",tblCong[[#This Row],[pCode]]) -> D01-S01-P05 | N25: =Paris!M$9 -> Gegibo | O25: K01 | P25: Mineneko
F26: =CONCATENATE(tblCong[[#This Row],[parishCode]],"-",tblCong[[#This Row],[kCode]]) -> D01-S01-P05-K02 | G26: =Distrik!F$5 -> D01 | H26: =VLOOKUP(tblCong[[#This Row],[distCode]],tblDistrict[#All],2) -> Kâte | I26: =Seket!I$5 -> S01 | J26: =CONCATENATE(tblCong[[#This Row],[distCode]],"-",tblCong[[#This Row],[sCode]]) -> D01-S01 | K26: =VLOOKUP(tblCong[[#This Row],[seketCode]],tblSeket[#All],5,FALSE) -> Kalasa | L26: =Paris!L$9 -> P05 | M26: =CONCATENATE(tblCong[[#This Row],[seketCode]],"-",tblCong[[#This Row],[pCode]]) -> D01-S01-P05 | N26: =Paris!M$9 -> Gegibo | O26: K02 | P26: Buamgo
F27: =CONCATENATE(tblCong[[#This Row],[parishCode]],"-",tblCong[[#This Row],[kCode]]) -> D01-S01-P05-K03 | G27: =Distrik!F$5 -> D01 | H27: =VLOOKUP(tblCong[[#This Row],[distCode]],tblDistrict[#All],2) -> Kâte | I27: =Seket!I$5 -> S01 | J27: =CONCATENATE(tblCong[[#This Row],[distCode]],"-",tblCong[[#This Row],[sCode]]) -> D01-S01 | K27: =VLOOKUP(tblCong[[#This Row],[seketCode]],tblSeket[#All],5,FALSE) -> Kalasa | L27: =Paris!L$9 -> P05 | M27: =CONCATENATE(tblCong[[#This Row],[seketCode]],"-",tblCong[[#This Row],[pCode]]) -> D01-S01-P05 | N27: =Paris!M$9 -> Gegibo | O27: K03 | P27: Zakupep
F28: =CONCATENATE(tblCong[[#This Row],[parishCode]],"-",tblCong[[#This Row],[kCode]]) -> D01-S01-P05-K04 | G28: =Distrik!F$5 -> D01 | H28: =VLOOKUP(tblCong[[#This Row],[distCode]],tblDistrict[#All],2) -> Kâte | I28: =Seket!I$5 -> S01 | J28: =CONCATENATE(tblCong[[#This Row],[distCode]],"-",tblCong[[#This Row],[sCode]]) -> D01-S01 | K28: =VLOOKUP(tblCong[[#This Row],[seketCode]],tblSeket[#All],5,FALSE) -> Kalasa | L28: =Paris!L$9 -> P05 | M28: =CONCATENATE(tblCong[[#This Row],[seketCode]],"-",tblCong[[#This Row],[pCode]]) -> D01-S01-P05 | N28: =Paris!M$9 -> Gegibo | O28: K04 | P28: Zankoa
F29: =CONCATENATE(tblCong[[#This Row],[parishCode]],"-",tblCong[[#This Row],[kCode]]) -> D01-S01-P05-K05 | G29: =Distrik!F$5 -> D01 | H29: =VLOOKUP(tblCong[[#This Row],[distCode]],tblDistrict[#All],2) -> Kâte | I29: =Seket!I$5 -> S01 | J29: =CONCATENATE(tblCong[[#This Row],[distCode]],"-",tblCong[[#This Row],[sCode]]) -> D01-S01 | K29: =VLOOKUP(tblCong[[#This Row],[seketCode]],tblSeket[#All],5,FALSE) -> Kalasa | L29: =Paris!L$9 -> P05 | M29: =CONCATENATE(tblCong[[#This Row],[seketCode]],"-",tblCong[[#This Row],[pCode]]) -> D01-S01-P05 | N29: =Paris!M$9 -> Gegibo | O29: K05 | P29: Karako
F30: =CONCATENATE(tblCong[[#This Row],[parishCode]],"-",tblCong[[#This Row],[kCode]]) -> D01-S01-P06-K01 | G30: =Distrik!F$5 -> D01 | H30: =VLOOKUP(tblCong[[#This Row],[distCode]],tblDistrict[#All],2) -> Kâte | I30: =Seket!I$5 -> S01 | J30: =CONCATENATE(tblCong[[#This Row],[distCode]],"-",tblCong[[#This Row],[sCode]]) -> D01-S01 | K30: =VLOOKUP(tblCong[[#This Row],[seketCode]],tblSeket[#All],5,FALSE) -> Kalasa | L30: =Paris!L$10 -> P06 | M30: =CONCATENATE(tblCong[[#This Row],[seketCode]],"-",tblCong[[#This Row],[pCode]]) -> D01-S01-P06 | N30: =Paris!M$10 -> Gitukia | O30: K01 | P30: Gitukia
F31: =CONCATENATE(tblCong[[#This Row],[parishCode]],"-",tblCong[[#This Row],[kCode]]) -> D01-S01-P06-K02 | G31: =Distrik!F$5 -> D01 | H31: =VLOOKUP(tblCong[[#This Row],[distCode]],tblDistrict[#All],2) -> Kâte | I31: =Seket!I$5 -> S01 | J31: =CONCATENATE(tblCong[[#This Row],[distCode]],"-",tblCong[[#This Row],[sCode]]) -> D01-S01 | K31: =VLOOKUP(tblCong[[#This Row],[seketCode]],tblSeket[#All],5,FALSE) -> Kalasa | L31: =Paris!L$10 -> P06 | M31: =CONCATENATE(tblCong[[#This Row],[seketCode]],"-",tblCong[[#This Row],[pCode]]) -> D01-S01-P06 | N31: =Paris!M$10 -> Gitukia | O31: K02 | P31: Qabi
F32: =CONCATENATE(tblCong[[#This Row],[parishCode]],"-",tblCong[[#This Row],[kCode]]) -> D01-S01-P06-K03 | G32: =Distrik!F$5 -> D01 | H32: =VLOOKUP(tblCong[[#This Row],[distCode]],tblDistrict[#All],2) -> Kâte | I32: =Seket!I$5 -> S01 | J32: =CONCATENATE(tblCong[[#This Row],[distCode]],"-",tblCong[[#This Row],[sCode]]) -> D01-S01 | K32: =VLOOKUP(tblCong[[#This Row],[seketCode]],tblSeket[#All],5,FALSE) -> Kalasa | L32: =Paris!L$10 -> P06 | M32: =CONCATENATE(tblCong[[#This Row],[seketCode]],"-",tblCong[[#This Row],[pCode]]) -> D01-S01-P06 | N32: =Paris!M$10 -> Gitukia | O32: K03 | P32: Ejango
F33: =CONCATENATE(tblCong[[#This Row],[parishCode]],"-",tblCong[[#This Row],[kCode]]) -> D01-S01-P06-K04 | G33: =Distrik!F$5 -> D01 | H33: =VLOOKUP(tblCong[[#This Row],[distCode]],tblDistrict[#All],2) -> Kâte | I33: =Seket!I$5 -> S01 | J33: =CONCATENATE(tblCong[[#This Row],[distCode]],"-",tblCong[[#This Row],[sCode]]) -> D01-S01 | K33: =VLOOKUP(tblCong[[#This Row],[seketCode]],tblSeket[#All],5,FALSE) -> Kalasa | L33: =Paris!L$10 -> P06 | M33: =CONCATENATE(tblCong[[#This Row],[seketCode]],"-",tblCong[[#This Row],[pCode]]) -> D01-S01-P06 | N33: =Paris!M$10 -> Gitukia | O33: K04 | P33: Kinalakna
F34: =CONCATENATE(tblCong[[#This Row],[parishCode]],"-",tblCong[[#This Row],[kCode]]) -> D01-S01-P07-K01 | G34: =Distrik!F$5 -> D01 | H34: =VLOOKUP(tblCong[[#This Row],[distCode]],tblDistrict[#All],2) -> Kâte | I34: =Seket!I$5 -> S01 | J34: =CONCATENATE(tblCong[[#This Row],[distCode]],"-",tblCong[[#This Row],[sCode]]) -> D01-S01 | K34: =VLOOKUP(tblCong[[#This Row],[seketCode]],tblSeket[#All],5,FALSE) -> Kalasa | L34: =Paris!L$11 -> P07 | M34: =CONCATENATE(tblCong[[#This Row],[seketCode]],"-",tblCong[[#This Row],[pCode]]) -> D01-S01-P07 | N34: =Paris!M$11 -> Botara | O34: K01 | P34: Gitua
F35: =CONCATENATE(tblCong[[#This Row],[parishCode]],"-",tblCong[[#This Row],[kCode]]) -> D01-S01-P07-K02 | G35: =Distrik!F$5 -> D01 | H35: =VLOOKUP(tblCong[[#This Row],[distCode]],tblDistrict[#All],2) -> Kâte | I35: =Seket!I$5 -> S01 | J35: =CONCATENATE(tblCong[[#This Row],[distCode]],"-",tblCong[[#This Row],[sCode]]) -> D01-S01 | K35: =VLOOKUP(tblCong[[#This Row],[seketCode]],tblSeket[#All],5,FALSE) -> Kalasa | L35: =Paris!L$11 -> P07 | M35: =CONCATENATE(tblCong[[#This Row],[seketCode]],"-",tblCong[[#This Row],[pCode]]) -> D01-S01-P07 | N35: =Paris!M$11 -> Botara | O35: K02 | P35: Boru
F36: =CONCATENATE(tblCong[[#This Row],[parishCode]],"-",tblCong[[#This Row],[kCode]]) -> D01-S01-P07-K03 | G36: =Distrik!F$5 -> D01 | H36: =VLOOKUP(tblCong[[#This Row],[distCode]],tblDistrict[#All],2) -> Kâte | I36: =Seket!I$5 -> S01 | J36: =CONCATENATE(tblCong[[#This Row],[distCode]],"-",tblCong[[#This Row],[sCode]]) -> D01-S01 | K36: =VLOOKUP(tblCong[[#This Row],[seketCode]],tblSeket[#All],5,FALSE) -> Kalasa | L36: =Paris!L$11 -> P07 | M36: =CONCATENATE(tblCong[[#This Row],[seketCode]],"-",tblCong[[#This Row],[pCode]]) -> D01-S01-P07 | N36: =Paris!M$11 -> Botara | O36: K03 | P36: Wenga
F37: =CONCATENATE(tblCong[[#This Row],[parishCode]],"-",tblCong[[#This Row],[kCode]]) -> D01-S01-P08-K01 | G37: =Distrik!F$5 -> D01 | H37: =VLOOKUP(tblCong[[#This Row],[distCode]],tblDistrict[#All],2) -> Kâte | I37: =Seket!I$5 -> S01 | J37: =CONCATENATE(tblCong[[#This Row],[distCode]],"-",tblCong[[#This Row],[sCode]]) -> D01-S01 | K37: =VLOOKUP(tblCong[[#This Row],[seketCode]],tblSeket[#All],5,FALSE) -> Kalasa | L37: =Paris!L$12 -> P08 | M37: =CONCATENATE(tblCong[[#This Row],[seketCode]],"-",tblCong[[#This Row],[pCode]]) -> D01-S01-P08 | N37: =Paris!M$12 -> Tibaki | O37: K01 | P37: Wagum
F38: =CONCATENATE(tblCong[[#This Row],[parishCode]],"-",tblCong[[#This Row],[kCode]]) -> D01-S01-P08-K02 | G38: =Distrik!F$5 -> D01 | H38: =VLOOKUP(tblCong[[#This Row],[distCode]],tblDistrict[#All],2) -> Kâte | I38: =Seket!I$5 -> S01 | J38: =CONCATENATE(tblCong[[#This Row],[distCode]],"-",tblCong[[#This Row],[sCode]]) -> D01-S01 | K38: =VLOOKUP(tblCong[[#This Row],[seketCode]],tblSeket[#All],5,FALSE) -> Kalasa | L38: =Paris!L$12 -> P08 | M38: =CONCATENATE(tblCong[[#This Row],[seketCode]],"-",tblCong[[#This Row],[pCode]]) -> D01-S01-P08 | N38: =Paris!M$12 -> Tibaki | O38: K02 | P38: Kolakia
F39: =CONCATENATE(tblCong[[#This Row],[parishCode]],"-",tblCong[[#This Row],[kCode]]) -> D01-S01-P08-K03 | G39: =Distrik!F$5 -> D01 | H39: =VLOOKUP(tblCong[[#This Row],[distCode]],tblDistrict[#All],2) -> Kâte | I39: =Seket!I$5 -> S01 | J39: =CONCATENATE(tblCong[[#This Row],[distCode]],"-",tblCong[[#This Row],[sCode]]) -> D01-S01 | K39: =VLOOKUP(tblCong[[#This Row],[seketCode]],tblSeket[#All],5,FALSE) -> Kalasa | L39: =Paris!L$12 -> P08 | M39: =CONCATENATE(tblCong[[#This Row],[seketCode]],"-",tblCong[[#This Row],[pCode]]) -> D01-S01-P08 | N39: =Paris!M$12 -> Tibaki | O39: K03 | P39: Kumukio
F40: =CONCATENATE(tblCong[[#This Row],[parishCode]],"-",tblCong[[#This Row],[kCode]]) -> D01-S01-P08-K04 | G40: =Distrik!F$5 -> D01 | H40: =VLOOKUP(tblCong[[#This Row],[distCode]],tblDistrict[#All],2) -> Kâte | I40: =Seket!I$5 -> S01 | J40: =CONCATENATE(tblCong[[#This Row],[distCode]],"-",tblCong[[#This Row],[sCode]]) -> D01-S01 | K40: =VLOOKUP(tblCong[[#This Row],[seketCode]],tblSeket[#All],5,FALSE) -> Kalasa | L40: =Paris!L$12 -> P08 | M40: =CONCATENATE(tblCong[[#This Row],[seketCode]],"-",tblCong[[#This Row],[pCode]]) -> D01-S01-P08 | N40: =Paris!M$12 -> Tibaki | O40: K04 | P40: Soleng
F41: =CONCATENATE(tblCong[[#This Row],[parishCode]],"-",tblCong[[#This Row],[kCode]]) -> D01-S02-P01-K01 | G41: =Distrik!F$5 -> D01 | H41: =VLOOKUP(tblCong[[#This Row],[distCode]],tblDistrict[#All],2) -> Kâte | I41: =Seket!I$6 -> S02 | J41: =CONCATENATE(tblCong[[#This Row],[distCode]],"-",tblCong[[#This Row],[sCode]]) -> D01-S02 | K41: =VLOOKUP(tblCong[[#This Row],[seketCode]],tblSeket[#All],5,FALSE) -> Dedua | L41: =Paris!L$13 -> P01 | M41: =CONCATENATE(tblCong[[#This Row],[seketCode]],"-",tblCong[[#This Row],[pCode]]) -> D01-S02-P01 | N41: =Paris!M$13 -> Yumeng | O41: K01 | P41: Yunziang
...
